'''
Erros são chamados de exceções

try:
    a= int(input('Numerador: '))
    b= int(input('Denominador: '))
    r = a/b
except Exception as erro:
    print(f'Infelizmente tivemos um problema: \033[31m{erro.__class__}\033[m')
else:
    print(f'O resultado é {r:.1f}')
finally:
    print('Volte sempre!')
'''

try:
    a= int(input('Numerador: '))
    b= int(input('Denominador: '))
    r = a/b
except (ValueError, TypeError):
    print(f'Infelizmente tivemos um problema com os dados digitados')
except ZeroDivisionError:
    print('Não é possível dividir um número por zero!')
except KeyboardInterrupt:
    print('O usuário preferiu não informar os dados!')
else:
    print(f'O resultado é {r:.1f}')
finally:
    print('Volte sempre!')